[2024-08-26T08:12:31.744+0700] {local_task_job_runner.py:123} INFO - ::group::Pre task execution logs
[2024-08-26T08:12:31.755+0700] {taskinstance.py:2603} INFO - Dependencies all met for dep_context=non-requeueable deps ti=<TaskInstance: combine_columns_dag.combine_columns scheduled__2024-01-01T00:00:00+00:00 [queued]>
[2024-08-26T08:12:31.761+0700] {taskinstance.py:2603} INFO - Dependencies all met for dep_context=requeueable deps ti=<TaskInstance: combine_columns_dag.combine_columns scheduled__2024-01-01T00:00:00+00:00 [queued]>
[2024-08-26T08:12:31.762+0700] {taskinstance.py:2856} INFO - Starting attempt 1 of 2
[2024-08-26T08:12:31.781+0700] {taskinstance.py:2879} INFO - Executing <Task(PythonOperator): combine_columns> on 2024-01-01 00:00:00+00:00
[2024-08-26T08:12:31.792+0700] {standard_task_runner.py:72} INFO - Started process 10996 to run task
[2024-08-26T08:12:31.833+0700] {standard_task_runner.py:104} INFO - Running: ['airflow', 'tasks', 'run', 'combine_columns_dag', 'combine_columns', 'scheduled__2024-01-01T00:00:00+00:00', '--job-id', '65', '--raw', '--subdir', 'DAGS_FOLDER/test_pandas.py', '--cfg-path', '/tmp/tmpmk1c28qe']
[2024-08-26T08:12:31.834+0700] {standard_task_runner.py:105} INFO - Job 65: Subtask combine_columns
[2024-08-26T08:12:32.031+0700] {task_command.py:467} INFO - Running <TaskInstance: combine_columns_dag.combine_columns scheduled__2024-01-01T00:00:00+00:00 [running]> on host LAPTOP-G8FSBU09.
[2024-08-26T08:12:32.198+0700] {taskinstance.py:3122} INFO - Exporting env vars: AIRFLOW_CTX_DAG_OWNER='airflow' AIRFLOW_CTX_DAG_ID='combine_columns_dag' AIRFLOW_CTX_TASK_ID='combine_columns' AIRFLOW_CTX_EXECUTION_DATE='2024-01-01T00:00:00+00:00' AIRFLOW_CTX_TRY_NUMBER='1' AIRFLOW_CTX_DAG_RUN_ID='scheduled__2024-01-01T00:00:00+00:00'
[2024-08-26T08:12:32.203+0700] {logging_mixin.py:190} INFO - Task instance is in running state
[2024-08-26T08:12:32.203+0700] {logging_mixin.py:190} INFO -  Previous state of the Task instance: queued
[2024-08-26T08:12:32.203+0700] {logging_mixin.py:190} INFO - Current task name:combine_columns state:running start_date:2024-08-26 01:12:31.756042+00:00
[2024-08-26T08:12:32.203+0700] {logging_mixin.py:190} INFO - Dag name:combine_columns_dag and current dag run status:running
[2024-08-26T08:12:32.204+0700] {taskinstance.py:731} INFO - ::endgroup::
[2024-08-26T08:12:32.235+0700] {taskinstance.py:3301} ERROR - Task failed with exception
Traceback (most recent call last):
  File "/home/user/.local/lib/python3.10/site-packages/pandas/core/indexes/base.py", line 3805, in get_loc
    return self._engine.get_loc(casted_key)
  File "index.pyx", line 167, in pandas._libs.index.IndexEngine.get_loc
  File "index.pyx", line 196, in pandas._libs.index.IndexEngine.get_loc
  File "pandas/_libs/hashtable_class_helper.pxi", line 7081, in pandas._libs.hashtable.PyObjectHashTable.get_item
  File "pandas/_libs/hashtable_class_helper.pxi", line 7089, in pandas._libs.hashtable.PyObjectHashTable.get_item
KeyError: 'a'

The above exception was the direct cause of the following exception:

Traceback (most recent call last):
  File "/home/user/.local/lib/python3.10/site-packages/airflow/models/taskinstance.py", line 767, in _execute_task
    result = _execute_callable(context=context, **execute_callable_kwargs)
  File "/home/user/.local/lib/python3.10/site-packages/airflow/models/taskinstance.py", line 733, in _execute_callable
    return ExecutionCallableRunner(
  File "/home/user/.local/lib/python3.10/site-packages/airflow/utils/operator_helpers.py", line 252, in run
    return self.func(*args, **kwargs)
  File "/home/user/.local/lib/python3.10/site-packages/airflow/models/baseoperator.py", line 406, in wrapper
    return func(self, *args, **kwargs)
  File "/home/user/.local/lib/python3.10/site-packages/airflow/operators/python.py", line 238, in execute
    return_value = self.execute_callable()
  File "/home/user/.local/lib/python3.10/site-packages/airflow/operators/python.py", line 256, in execute_callable
    return runner.run(*self.op_args, **self.op_kwargs)
  File "/home/user/.local/lib/python3.10/site-packages/airflow/utils/operator_helpers.py", line 252, in run
    return self.func(*args, **kwargs)
  File "/home/user/airflow/dags/test_pandas.py", line 16, in comb_col
    df['combined']= df['a'].astype(str) + df['b'].astype(str)
  File "/home/user/.local/lib/python3.10/site-packages/pandas/core/frame.py", line 4102, in __getitem__
    indexer = self.columns.get_loc(key)
  File "/home/user/.local/lib/python3.10/site-packages/pandas/core/indexes/base.py", line 3812, in get_loc
    raise KeyError(key) from err
KeyError: 'a'
[2024-08-26T08:12:32.337+0700] {logging_mixin.py:190} INFO - Task instance in failure state
[2024-08-26T08:12:32.338+0700] {logging_mixin.py:190} INFO - Task start:2024-08-26 01:12:31.756042+00:00 end:2024-08-26 01:12:32.336166+00:00 duration:0.580124
[2024-08-26T08:12:32.339+0700] {logging_mixin.py:190} INFO - Task:<Task(PythonOperator): combine_columns> dag:<DAG: combine_columns_dag> dagrun:<DagRun combine_columns_dag @ 2024-01-01 00:00:00+00:00: scheduled__2024-01-01T00:00:00+00:00, state:running, queued_at: 2024-08-26 01:12:27.788751+00:00. externally triggered: False>
[2024-08-26T08:12:32.339+0700] {logging_mixin.py:190} INFO - Failure caused by 'a'
[2024-08-26T08:12:32.340+0700] {taskinstance.py:1225} INFO - Marking task as UP_FOR_RETRY. dag_id=combine_columns_dag, task_id=combine_columns, run_id=scheduled__2024-01-01T00:00:00+00:00, execution_date=20240101T000000, start_date=20240826T011231, end_date=20240826T011232
[2024-08-26T08:12:32.373+0700] {taskinstance.py:340} INFO - ::group::Post task execution logs
[2024-08-26T08:12:32.374+0700] {standard_task_runner.py:124} ERROR - Failed to execute job 65 for task combine_columns ('a'; 10996)
Traceback (most recent call last):
  File "/home/user/.local/lib/python3.10/site-packages/pandas/core/indexes/base.py", line 3805, in get_loc
    return self._engine.get_loc(casted_key)
  File "index.pyx", line 167, in pandas._libs.index.IndexEngine.get_loc
  File "index.pyx", line 196, in pandas._libs.index.IndexEngine.get_loc
  File "pandas/_libs/hashtable_class_helper.pxi", line 7081, in pandas._libs.hashtable.PyObjectHashTable.get_item
  File "pandas/_libs/hashtable_class_helper.pxi", line 7089, in pandas._libs.hashtable.PyObjectHashTable.get_item
KeyError: 'a'

The above exception was the direct cause of the following exception:

Traceback (most recent call last):
  File "/home/user/.local/lib/python3.10/site-packages/airflow/task/task_runner/standard_task_runner.py", line 117, in _start_by_fork
    ret = args.func(args, dag=self.dag)
  File "/home/user/.local/lib/python3.10/site-packages/airflow/cli/cli_config.py", line 49, in command
    return func(*args, **kwargs)
  File "/home/user/.local/lib/python3.10/site-packages/airflow/utils/cli.py", line 115, in wrapper
    return f(*args, **kwargs)
  File "/home/user/.local/lib/python3.10/site-packages/airflow/cli/commands/task_command.py", line 483, in task_run
    task_return_code = _run_task_by_selected_method(args, _dag, ti)
  File "/home/user/.local/lib/python3.10/site-packages/airflow/cli/commands/task_command.py", line 256, in _run_task_by_selected_method
    return _run_raw_task(args, ti)
  File "/home/user/.local/lib/python3.10/site-packages/airflow/cli/commands/task_command.py", line 341, in _run_raw_task
    return ti._run_raw_task(
  File "/home/user/.local/lib/python3.10/site-packages/airflow/utils/session.py", line 97, in wrapper
    return func(*args, session=session, **kwargs)
  File "/home/user/.local/lib/python3.10/site-packages/airflow/models/taskinstance.py", line 2995, in _run_raw_task
    return _run_raw_task(
  File "/home/user/.local/lib/python3.10/site-packages/airflow/models/taskinstance.py", line 273, in _run_raw_task
    TaskInstance._execute_task_with_callbacks(
  File "/home/user/.local/lib/python3.10/site-packages/airflow/models/taskinstance.py", line 3149, in _execute_task_with_callbacks
    result = self._execute_task(context, task_orig)
  File "/home/user/.local/lib/python3.10/site-packages/airflow/models/taskinstance.py", line 3173, in _execute_task
    return _execute_task(self, context, task_orig)
  File "/home/user/.local/lib/python3.10/site-packages/airflow/models/taskinstance.py", line 767, in _execute_task
    result = _execute_callable(context=context, **execute_callable_kwargs)
  File "/home/user/.local/lib/python3.10/site-packages/airflow/models/taskinstance.py", line 733, in _execute_callable
    return ExecutionCallableRunner(
  File "/home/user/.local/lib/python3.10/site-packages/airflow/utils/operator_helpers.py", line 252, in run
    return self.func(*args, **kwargs)
  File "/home/user/.local/lib/python3.10/site-packages/airflow/models/baseoperator.py", line 406, in wrapper
    return func(self, *args, **kwargs)
  File "/home/user/.local/lib/python3.10/site-packages/airflow/operators/python.py", line 238, in execute
    return_value = self.execute_callable()
  File "/home/user/.local/lib/python3.10/site-packages/airflow/operators/python.py", line 256, in execute_callable
    return runner.run(*self.op_args, **self.op_kwargs)
  File "/home/user/.local/lib/python3.10/site-packages/airflow/utils/operator_helpers.py", line 252, in run
    return self.func(*args, **kwargs)
  File "/home/user/airflow/dags/test_pandas.py", line 16, in comb_col
    df['combined']= df['a'].astype(str) + df['b'].astype(str)
  File "/home/user/.local/lib/python3.10/site-packages/pandas/core/frame.py", line 4102, in __getitem__
    indexer = self.columns.get_loc(key)
  File "/home/user/.local/lib/python3.10/site-packages/pandas/core/indexes/base.py", line 3812, in get_loc
    raise KeyError(key) from err
KeyError: 'a'
[2024-08-26T08:12:32.404+0700] {local_task_job_runner.py:261} INFO - Task exited with return code 1
[2024-08-26T08:12:32.422+0700] {taskinstance.py:3891} INFO - 0 downstream tasks scheduled from follow-on schedule check
[2024-08-26T08:12:32.422+0700] {local_task_job_runner.py:240} INFO - ::endgroup::
[2024-08-26T08:14:01.994+0700] {local_task_job_runner.py:123} INFO - ::group::Pre task execution logs
[2024-08-26T08:14:02.005+0700] {taskinstance.py:2603} INFO - Dependencies all met for dep_context=non-requeueable deps ti=<TaskInstance: combine_columns_dag.combine_columns scheduled__2024-01-01T00:00:00+00:00 [queued]>
[2024-08-26T08:14:02.011+0700] {taskinstance.py:2603} INFO - Dependencies all met for dep_context=requeueable deps ti=<TaskInstance: combine_columns_dag.combine_columns scheduled__2024-01-01T00:00:00+00:00 [queued]>
[2024-08-26T08:14:02.012+0700] {taskinstance.py:2856} INFO - Starting attempt 1 of 2
[2024-08-26T08:14:02.034+0700] {taskinstance.py:2879} INFO - Executing <Task(PythonOperator): combine_columns> on 2024-01-01 00:00:00+00:00
[2024-08-26T08:14:02.046+0700] {standard_task_runner.py:72} INFO - Started process 12021 to run task
[2024-08-26T08:14:02.066+0700] {standard_task_runner.py:104} INFO - Running: ['airflow', 'tasks', 'run', 'combine_columns_dag', 'combine_columns', 'scheduled__2024-01-01T00:00:00+00:00', '--job-id', '66', '--raw', '--subdir', 'DAGS_FOLDER/test_pandas.py', '--cfg-path', '/tmp/tmp6bghhcwj']
[2024-08-26T08:14:02.067+0700] {standard_task_runner.py:105} INFO - Job 66: Subtask combine_columns
[2024-08-26T08:14:02.206+0700] {task_command.py:467} INFO - Running <TaskInstance: combine_columns_dag.combine_columns scheduled__2024-01-01T00:00:00+00:00 [running]> on host LAPTOP-G8FSBU09.
[2024-08-26T08:14:02.315+0700] {taskinstance.py:3122} INFO - Exporting env vars: AIRFLOW_CTX_DAG_OWNER='airflow' AIRFLOW_CTX_DAG_ID='combine_columns_dag' AIRFLOW_CTX_TASK_ID='combine_columns' AIRFLOW_CTX_EXECUTION_DATE='2024-01-01T00:00:00+00:00' AIRFLOW_CTX_TRY_NUMBER='1' AIRFLOW_CTX_DAG_RUN_ID='scheduled__2024-01-01T00:00:00+00:00'
[2024-08-26T08:14:02.318+0700] {logging_mixin.py:190} INFO - Task instance is in running state
[2024-08-26T08:14:02.318+0700] {logging_mixin.py:190} INFO -  Previous state of the Task instance: queued
[2024-08-26T08:14:02.318+0700] {logging_mixin.py:190} INFO - Current task name:combine_columns state:running start_date:2024-08-26 01:14:02.005306+00:00
[2024-08-26T08:14:02.319+0700] {logging_mixin.py:190} INFO - Dag name:combine_columns_dag and current dag run status:running
[2024-08-26T08:14:02.319+0700] {taskinstance.py:731} INFO - ::endgroup::
[2024-08-26T08:14:02.371+0700] {python.py:240} INFO - Done. Returned value was: None
[2024-08-26T08:14:02.376+0700] {taskinstance.py:340} INFO - ::group::Post task execution logs
[2024-08-26T08:14:02.377+0700] {taskinstance.py:352} INFO - Marking task as SUCCESS. dag_id=combine_columns_dag, task_id=combine_columns, run_id=scheduled__2024-01-01T00:00:00+00:00, execution_date=20240101T000000, start_date=20240826T011402, end_date=20240826T011402
[2024-08-26T08:14:02.392+0700] {logging_mixin.py:190} INFO - Task instance in success state
[2024-08-26T08:14:02.393+0700] {logging_mixin.py:190} INFO -  Previous state of the Task instance: running
[2024-08-26T08:14:02.393+0700] {logging_mixin.py:190} INFO - Dag name:combine_columns_dag queued_at:2024-08-26 01:13:57.843979+00:00
[2024-08-26T08:14:02.393+0700] {logging_mixin.py:190} INFO - Task hostname:LAPTOP-G8FSBU09. operator:PythonOperator
[2024-08-26T08:14:02.401+0700] {local_task_job_runner.py:261} INFO - Task exited with return code 0
[2024-08-26T08:14:02.418+0700] {taskinstance.py:3891} INFO - 0 downstream tasks scheduled from follow-on schedule check
[2024-08-26T08:14:02.419+0700] {local_task_job_runner.py:240} INFO - ::endgroup::
