[2024-08-22T11:07:14.780+0700] {local_task_job_runner.py:123} INFO - ::group::Pre task execution logs
[2024-08-22T11:07:14.794+0700] {taskinstance.py:2603} INFO - Dependencies all met for dep_context=non-requeueable deps ti=<TaskInstance: query_user_table_sqlite.query_user_table manual__2024-08-22T04:07:10.544490+00:00 [queued]>
[2024-08-22T11:07:14.800+0700] {taskinstance.py:2603} INFO - Dependencies all met for dep_context=requeueable deps ti=<TaskInstance: query_user_table_sqlite.query_user_table manual__2024-08-22T04:07:10.544490+00:00 [queued]>
[2024-08-22T11:07:14.800+0700] {taskinstance.py:2856} INFO - Starting attempt 1 of 2
[2024-08-22T11:07:14.819+0700] {taskinstance.py:2879} INFO - Executing <Task(SqliteOperator): query_user_table> on 2024-08-22 04:07:10.544490+00:00
[2024-08-22T11:07:14.826+0700] {standard_task_runner.py:72} INFO - Started process 27327 to run task
[2024-08-22T11:07:14.873+0700] {standard_task_runner.py:104} INFO - Running: ['airflow', 'tasks', 'run', 'query_user_table_sqlite', 'query_user_table', 'manual__2024-08-22T04:07:10.544490+00:00', '--job-id', '284', '--raw', '--subdir', 'DAGS_FOLDER/test_slqite.py', '--cfg-path', '/tmp/tmp4q2a5owp']
[2024-08-22T11:07:14.874+0700] {standard_task_runner.py:105} INFO - Job 284: Subtask query_user_table
[2024-08-22T11:07:15.120+0700] {task_command.py:467} INFO - Running <TaskInstance: query_user_table_sqlite.query_user_table manual__2024-08-22T04:07:10.544490+00:00 [running]> on host LAPTOP-G8FSBU09.
[2024-08-22T11:07:15.240+0700] {taskinstance.py:3122} INFO - Exporting env vars: AIRFLOW_CTX_DAG_OWNER='airflow' AIRFLOW_CTX_DAG_ID='query_user_table_sqlite' AIRFLOW_CTX_TASK_ID='query_user_table' AIRFLOW_CTX_EXECUTION_DATE='2024-08-22T04:07:10.544490+00:00' AIRFLOW_CTX_TRY_NUMBER='1' AIRFLOW_CTX_DAG_RUN_ID='manual__2024-08-22T04:07:10.544490+00:00'
[2024-08-22T11:07:15.249+0700] {logging_mixin.py:190} INFO - Task instance is in running state
[2024-08-22T11:07:15.249+0700] {logging_mixin.py:190} INFO -  Previous state of the Task instance: queued
[2024-08-22T11:07:15.250+0700] {logging_mixin.py:190} INFO - Current task name:query_user_table state:running start_date:2024-08-22 04:07:14.794514+00:00
[2024-08-22T11:07:15.250+0700] {logging_mixin.py:190} INFO - Dag name:query_user_table_sqlite and current dag run status:running
[2024-08-22T11:07:15.250+0700] {taskinstance.py:731} INFO - ::endgroup::
[2024-08-22T11:07:15.251+0700] {sql.py:282} INFO - Executing: select * from user;
[2024-08-22T11:07:15.262+0700] {base.py:84} INFO - Retrieving connection 'test_sqlite'
[2024-08-22T11:07:15.273+0700] {base.py:84} INFO - Retrieving connection 'test_sqlite'
[2024-08-22T11:07:15.273+0700] {sql.py:509} INFO - Running statement: select * from user;, parameters: None
[2024-08-22T11:07:15.274+0700] {taskinstance.py:3301} ERROR - Task failed with exception
Traceback (most recent call last):
  File "/home/user/.local/lib/python3.10/site-packages/airflow/models/taskinstance.py", line 767, in _execute_task
    result = _execute_callable(context=context, **execute_callable_kwargs)
  File "/home/user/.local/lib/python3.10/site-packages/airflow/models/taskinstance.py", line 733, in _execute_callable
    return ExecutionCallableRunner(
  File "/home/user/.local/lib/python3.10/site-packages/airflow/utils/operator_helpers.py", line 252, in run
    return self.func(*args, **kwargs)
  File "/home/user/.local/lib/python3.10/site-packages/airflow/models/baseoperator.py", line 406, in wrapper
    return func(self, *args, **kwargs)
  File "/home/user/.local/lib/python3.10/site-packages/airflow/providers/common/sql/operators/sql.py", line 288, in execute
    output = hook.run(
  File "/home/user/.local/lib/python3.10/site-packages/airflow/providers/common/sql/hooks/sql.py", line 456, in run
    self._run_command(cur, sql_statement, parameters)
  File "/home/user/.local/lib/python3.10/site-packages/airflow/providers/common/sql/hooks/sql.py", line 514, in _run_command
    cur.execute(sql_statement)
sqlite3.OperationalError: no such table: user
[2024-08-22T11:07:15.296+0700] {logging_mixin.py:190} INFO - Task instance in failure state
[2024-08-22T11:07:15.296+0700] {logging_mixin.py:190} INFO - Task start:2024-08-22 04:07:14.794514+00:00 end:2024-08-22 04:07:15.293817+00:00 duration:0.499303
[2024-08-22T11:07:15.296+0700] {logging_mixin.py:190} INFO - Task:<Task(SqliteOperator): query_user_table> dag:<DAG: query_user_table_sqlite> dagrun:<DagRun query_user_table_sqlite @ 2024-08-22 04:07:10.544490+00:00: manual__2024-08-22T04:07:10.544490+00:00, state:running, queued_at: 2024-08-22 04:07:10.769416+00:00. externally triggered: True>
[2024-08-22T11:07:15.297+0700] {logging_mixin.py:190} INFO - Failure caused by no such table: user
[2024-08-22T11:07:15.297+0700] {taskinstance.py:1225} INFO - Marking task as UP_FOR_RETRY. dag_id=query_user_table_sqlite, task_id=query_user_table, run_id=manual__2024-08-22T04:07:10.544490+00:00, execution_date=20240822T040710, start_date=20240822T040714, end_date=20240822T040715
[2024-08-22T11:07:15.323+0700] {taskinstance.py:340} INFO - ::group::Post task execution logs
[2024-08-22T11:07:15.324+0700] {standard_task_runner.py:124} ERROR - Failed to execute job 284 for task query_user_table (no such table: user; 27327)
Traceback (most recent call last):
  File "/home/user/.local/lib/python3.10/site-packages/airflow/task/task_runner/standard_task_runner.py", line 117, in _start_by_fork
    ret = args.func(args, dag=self.dag)
  File "/home/user/.local/lib/python3.10/site-packages/airflow/cli/cli_config.py", line 49, in command
    return func(*args, **kwargs)
  File "/home/user/.local/lib/python3.10/site-packages/airflow/utils/cli.py", line 115, in wrapper
    return f(*args, **kwargs)
  File "/home/user/.local/lib/python3.10/site-packages/airflow/cli/commands/task_command.py", line 483, in task_run
    task_return_code = _run_task_by_selected_method(args, _dag, ti)
  File "/home/user/.local/lib/python3.10/site-packages/airflow/cli/commands/task_command.py", line 256, in _run_task_by_selected_method
    return _run_raw_task(args, ti)
  File "/home/user/.local/lib/python3.10/site-packages/airflow/cli/commands/task_command.py", line 341, in _run_raw_task
    return ti._run_raw_task(
  File "/home/user/.local/lib/python3.10/site-packages/airflow/utils/session.py", line 97, in wrapper
    return func(*args, session=session, **kwargs)
  File "/home/user/.local/lib/python3.10/site-packages/airflow/models/taskinstance.py", line 2995, in _run_raw_task
    return _run_raw_task(
  File "/home/user/.local/lib/python3.10/site-packages/airflow/models/taskinstance.py", line 273, in _run_raw_task
    TaskInstance._execute_task_with_callbacks(
  File "/home/user/.local/lib/python3.10/site-packages/airflow/models/taskinstance.py", line 3149, in _execute_task_with_callbacks
    result = self._execute_task(context, task_orig)
  File "/home/user/.local/lib/python3.10/site-packages/airflow/models/taskinstance.py", line 3173, in _execute_task
    return _execute_task(self, context, task_orig)
  File "/home/user/.local/lib/python3.10/site-packages/airflow/models/taskinstance.py", line 767, in _execute_task
    result = _execute_callable(context=context, **execute_callable_kwargs)
  File "/home/user/.local/lib/python3.10/site-packages/airflow/models/taskinstance.py", line 733, in _execute_callable
    return ExecutionCallableRunner(
  File "/home/user/.local/lib/python3.10/site-packages/airflow/utils/operator_helpers.py", line 252, in run
    return self.func(*args, **kwargs)
  File "/home/user/.local/lib/python3.10/site-packages/airflow/models/baseoperator.py", line 406, in wrapper
    return func(self, *args, **kwargs)
  File "/home/user/.local/lib/python3.10/site-packages/airflow/providers/common/sql/operators/sql.py", line 288, in execute
    output = hook.run(
  File "/home/user/.local/lib/python3.10/site-packages/airflow/providers/common/sql/hooks/sql.py", line 456, in run
    self._run_command(cur, sql_statement, parameters)
  File "/home/user/.local/lib/python3.10/site-packages/airflow/providers/common/sql/hooks/sql.py", line 514, in _run_command
    cur.execute(sql_statement)
sqlite3.OperationalError: no such table: user
[2024-08-22T11:07:15.361+0700] {local_task_job_runner.py:261} INFO - Task exited with return code 1
[2024-08-22T11:07:15.370+0700] {taskinstance.py:3891} INFO - 0 downstream tasks scheduled from follow-on schedule check
[2024-08-22T11:07:15.371+0700] {local_task_job_runner.py:240} INFO - ::endgroup::
