[2024-08-27T09:35:42.149+0700] {local_task_job_runner.py:123} INFO - ::group::Pre task execution logs
[2024-08-27T09:35:42.158+0700] {taskinstance.py:2603} INFO - Dependencies all met for dep_context=non-requeueable deps ti=<TaskInstance: run_notebook_and_return_first_5_rows.run_notebook_task manual__2024-08-27T02:35:38.366475+00:00 [queued]>
[2024-08-27T09:35:42.163+0700] {taskinstance.py:2603} INFO - Dependencies all met for dep_context=requeueable deps ti=<TaskInstance: run_notebook_and_return_first_5_rows.run_notebook_task manual__2024-08-27T02:35:38.366475+00:00 [queued]>
[2024-08-27T09:35:42.164+0700] {taskinstance.py:2856} INFO - Starting attempt 1 of 2
[2024-08-27T09:35:42.176+0700] {taskinstance.py:2879} INFO - Executing <Task(PythonOperator): run_notebook_task> on 2024-08-27 02:35:38.366475+00:00
[2024-08-27T09:35:42.182+0700] {standard_task_runner.py:72} INFO - Started process 13110 to run task
[2024-08-27T09:35:42.186+0700] {standard_task_runner.py:104} INFO - Running: ['airflow', 'tasks', 'run', 'run_notebook_and_return_first_5_rows', 'run_notebook_task', 'manual__2024-08-27T02:35:38.366475+00:00', '--job-id', '178', '--raw', '--subdir', 'DAGS_FOLDER/test_jupyter.py', '--cfg-path', '/tmp/tmpw4vsnm5w']
[2024-08-27T09:35:42.186+0700] {standard_task_runner.py:105} INFO - Job 178: Subtask run_notebook_task
[2024-08-27T09:35:42.242+0700] {task_command.py:467} INFO - Running <TaskInstance: run_notebook_and_return_first_5_rows.run_notebook_task manual__2024-08-27T02:35:38.366475+00:00 [running]> on host LAPTOP-G8FSBU09.
[2024-08-27T09:35:42.304+0700] {taskinstance.py:3122} INFO - Exporting env vars: AIRFLOW_CTX_DAG_OWNER='airflow' AIRFLOW_CTX_DAG_ID='run_notebook_and_return_first_5_rows' AIRFLOW_CTX_TASK_ID='run_notebook_task' AIRFLOW_CTX_EXECUTION_DATE='2024-08-27T02:35:38.366475+00:00' AIRFLOW_CTX_TRY_NUMBER='1' AIRFLOW_CTX_DAG_RUN_ID='manual__2024-08-27T02:35:38.366475+00:00'
[2024-08-27T09:35:42.305+0700] {logging_mixin.py:190} INFO - Task instance is in running state
[2024-08-27T09:35:42.306+0700] {logging_mixin.py:190} INFO -  Previous state of the Task instance: queued
[2024-08-27T09:35:42.306+0700] {logging_mixin.py:190} INFO - Current task name:run_notebook_task state:running start_date:2024-08-27 02:35:42.158889+00:00
[2024-08-27T09:35:42.306+0700] {logging_mixin.py:190} INFO - Dag name:run_notebook_and_return_first_5_rows and current dag run status:running
[2024-08-27T09:35:42.306+0700] {taskinstance.py:731} INFO - ::endgroup::
[2024-08-27T09:35:42.307+0700] {execute.py:83} INFO - Input Notebook:  /home/user/airflow/dags/data_clean.ipynb
[2024-08-27T09:35:42.307+0700] {execute.py:84} INFO - Output Notebook: /home/user/airflow/dags/data_clean_2.ipynb
[2024-08-27T09:35:42.423+0700] {logging_mixin.py:190} WARNING - Executing:   0%|          | 0/5 [00:00<?, ?cell/s]
[2024-08-27T09:35:42.484+0700] {kernelspec.py:284} WARNING - Kernelspec name python3 cannot be found!
[2024-08-27T09:35:42.484+0700] {manager.py:95} ERROR - No such kernel named python3
Traceback (most recent call last):
  File "/home/user/.local/lib/python3.10/site-packages/jupyter_client/manager.py", line 87, in wrapper
    out = await method(self, *args, **kwargs)
  File "/home/user/.local/lib/python3.10/site-packages/jupyter_client/manager.py", line 435, in _async_start_kernel
    kernel_cmd, kw = await self._async_pre_start_kernel(**kw)
  File "/home/user/.local/lib/python3.10/site-packages/jupyter_client/manager.py", line 397, in _async_pre_start_kernel
    self.kernel_spec,
  File "/home/user/.local/lib/python3.10/site-packages/jupyter_client/manager.py", line 195, in kernel_spec
    self._kernel_spec = self.kernel_spec_manager.get_kernel_spec(self.kernel_name)
  File "/home/user/.local/lib/python3.10/site-packages/jupyter_client/kernelspec.py", line 285, in get_kernel_spec
    raise NoSuchKernel(kernel_name)
jupyter_client.kernelspec.NoSuchKernel: No such kernel named python3
[2024-08-27T09:35:42.486+0700] {logging_mixin.py:190} WARNING - Executing:   0%|          | 0/5 [00:00<?, ?cell/s]
[2024-08-27T09:35:42.487+0700] {taskinstance.py:3301} ERROR - Task failed with exception
Traceback (most recent call last):
  File "/home/user/.local/lib/python3.10/site-packages/airflow/models/taskinstance.py", line 767, in _execute_task
    result = _execute_callable(context=context, **execute_callable_kwargs)
  File "/home/user/.local/lib/python3.10/site-packages/airflow/models/taskinstance.py", line 733, in _execute_callable
    return ExecutionCallableRunner(
  File "/home/user/.local/lib/python3.10/site-packages/airflow/utils/operator_helpers.py", line 252, in run
    return self.func(*args, **kwargs)
  File "/home/user/.local/lib/python3.10/site-packages/airflow/models/baseoperator.py", line 406, in wrapper
    return func(self, *args, **kwargs)
  File "/home/user/.local/lib/python3.10/site-packages/airflow/operators/python.py", line 238, in execute
    return_value = self.execute_callable()
  File "/home/user/.local/lib/python3.10/site-packages/airflow/operators/python.py", line 256, in execute_callable
    return runner.run(*self.op_args, **self.op_kwargs)
  File "/home/user/.local/lib/python3.10/site-packages/airflow/utils/operator_helpers.py", line 252, in run
    return self.func(*args, **kwargs)
  File "/home/user/airflow/dags/test_jupyter.py", line 13, in run_notebook
    pm.execute_notebook(
  File "/home/user/.local/lib/python3.10/site-packages/papermill/execute.py", line 116, in execute_notebook
    nb = papermill_engines.execute_notebook_with_engine(
  File "/home/user/.local/lib/python3.10/site-packages/papermill/engines.py", line 48, in execute_notebook_with_engine
    return self.get_engine(engine_name).execute_notebook(nb, kernel_name, **kwargs)
  File "/home/user/.local/lib/python3.10/site-packages/papermill/engines.py", line 370, in execute_notebook
    cls.execute_managed_notebook(nb_man, kernel_name, log_output=log_output, **kwargs)
  File "/home/user/.local/lib/python3.10/site-packages/papermill/engines.py", line 442, in execute_managed_notebook
    return PapermillNotebookClient(nb_man, **final_kwargs).execute()
  File "/home/user/.local/lib/python3.10/site-packages/papermill/clientwrap.py", line 43, in execute
    with self.setup_kernel(**kwargs):
  File "/usr/lib/python3.10/contextlib.py", line 135, in __enter__
    return next(self.gen)
  File "/home/user/.local/lib/python3.10/site-packages/nbclient/client.py", line 600, in setup_kernel
    self.start_new_kernel(**kwargs)
  File "/home/user/.local/lib/python3.10/site-packages/jupyter_core/utils/__init__.py", line 165, in wrapped
    return loop.run_until_complete(inner)
  File "/usr/lib/python3.10/asyncio/base_events.py", line 649, in run_until_complete
    return future.result()
  File "/home/user/.local/lib/python3.10/site-packages/nbclient/client.py", line 550, in async_start_new_kernel
    await ensure_async(self.km.start_kernel(extra_arguments=self.extra_arguments, **kwargs))
  File "/home/user/.local/lib/python3.10/site-packages/jupyter_core/utils/__init__.py", line 198, in ensure_async
    result = await obj
  File "/home/user/.local/lib/python3.10/site-packages/jupyter_client/manager.py", line 96, in wrapper
    raise e
  File "/home/user/.local/lib/python3.10/site-packages/jupyter_client/manager.py", line 87, in wrapper
    out = await method(self, *args, **kwargs)
  File "/home/user/.local/lib/python3.10/site-packages/jupyter_client/manager.py", line 435, in _async_start_kernel
    kernel_cmd, kw = await self._async_pre_start_kernel(**kw)
  File "/home/user/.local/lib/python3.10/site-packages/jupyter_client/manager.py", line 397, in _async_pre_start_kernel
    self.kernel_spec,
  File "/home/user/.local/lib/python3.10/site-packages/jupyter_client/manager.py", line 195, in kernel_spec
    self._kernel_spec = self.kernel_spec_manager.get_kernel_spec(self.kernel_name)
  File "/home/user/.local/lib/python3.10/site-packages/jupyter_client/kernelspec.py", line 285, in get_kernel_spec
    raise NoSuchKernel(kernel_name)
jupyter_client.kernelspec.NoSuchKernel: No such kernel named python3
[2024-08-27T09:35:42.498+0700] {logging_mixin.py:190} INFO - Task instance in failure state
[2024-08-27T09:35:42.499+0700] {logging_mixin.py:190} INFO - Task start:2024-08-27 02:35:42.158889+00:00 end:2024-08-27 02:35:42.498153+00:00 duration:0.339264
[2024-08-27T09:35:42.499+0700] {logging_mixin.py:190} INFO - Task:<Task(PythonOperator): run_notebook_task> dag:<DAG: run_notebook_and_return_first_5_rows> dagrun:<DagRun run_notebook_and_return_first_5_rows @ 2024-08-27 02:35:38.366475+00:00: manual__2024-08-27T02:35:38.366475+00:00, state:running, queued_at: 2024-08-27 02:35:38.396174+00:00. externally triggered: True>
[2024-08-27T09:35:42.499+0700] {logging_mixin.py:190} INFO - Failure caused by No such kernel named python3
[2024-08-27T09:35:42.499+0700] {taskinstance.py:1225} INFO - Marking task as UP_FOR_RETRY. dag_id=run_notebook_and_return_first_5_rows, task_id=run_notebook_task, run_id=manual__2024-08-27T02:35:38.366475+00:00, execution_date=20240827T023538, start_date=20240827T023542, end_date=20240827T023542
[2024-08-27T09:35:42.518+0700] {taskinstance.py:340} INFO - ::group::Post task execution logs
[2024-08-27T09:35:42.518+0700] {standard_task_runner.py:124} ERROR - Failed to execute job 178 for task run_notebook_task (No such kernel named python3; 13110)
Traceback (most recent call last):
  File "/home/user/.local/lib/python3.10/site-packages/airflow/task/task_runner/standard_task_runner.py", line 117, in _start_by_fork
    ret = args.func(args, dag=self.dag)
  File "/home/user/.local/lib/python3.10/site-packages/airflow/cli/cli_config.py", line 49, in command
    return func(*args, **kwargs)
  File "/home/user/.local/lib/python3.10/site-packages/airflow/utils/cli.py", line 115, in wrapper
    return f(*args, **kwargs)
  File "/home/user/.local/lib/python3.10/site-packages/airflow/cli/commands/task_command.py", line 483, in task_run
    task_return_code = _run_task_by_selected_method(args, _dag, ti)
  File "/home/user/.local/lib/python3.10/site-packages/airflow/cli/commands/task_command.py", line 256, in _run_task_by_selected_method
    return _run_raw_task(args, ti)
  File "/home/user/.local/lib/python3.10/site-packages/airflow/cli/commands/task_command.py", line 341, in _run_raw_task
    return ti._run_raw_task(
  File "/home/user/.local/lib/python3.10/site-packages/airflow/utils/session.py", line 97, in wrapper
    return func(*args, session=session, **kwargs)
  File "/home/user/.local/lib/python3.10/site-packages/airflow/models/taskinstance.py", line 2995, in _run_raw_task
    return _run_raw_task(
  File "/home/user/.local/lib/python3.10/site-packages/airflow/models/taskinstance.py", line 273, in _run_raw_task
    TaskInstance._execute_task_with_callbacks(
  File "/home/user/.local/lib/python3.10/site-packages/airflow/models/taskinstance.py", line 3149, in _execute_task_with_callbacks
    result = self._execute_task(context, task_orig)
  File "/home/user/.local/lib/python3.10/site-packages/airflow/models/taskinstance.py", line 3173, in _execute_task
    return _execute_task(self, context, task_orig)
  File "/home/user/.local/lib/python3.10/site-packages/airflow/models/taskinstance.py", line 767, in _execute_task
    result = _execute_callable(context=context, **execute_callable_kwargs)
  File "/home/user/.local/lib/python3.10/site-packages/airflow/models/taskinstance.py", line 733, in _execute_callable
    return ExecutionCallableRunner(
  File "/home/user/.local/lib/python3.10/site-packages/airflow/utils/operator_helpers.py", line 252, in run
    return self.func(*args, **kwargs)
  File "/home/user/.local/lib/python3.10/site-packages/airflow/models/baseoperator.py", line 406, in wrapper
    return func(self, *args, **kwargs)
  File "/home/user/.local/lib/python3.10/site-packages/airflow/operators/python.py", line 238, in execute
    return_value = self.execute_callable()
  File "/home/user/.local/lib/python3.10/site-packages/airflow/operators/python.py", line 256, in execute_callable
    return runner.run(*self.op_args, **self.op_kwargs)
  File "/home/user/.local/lib/python3.10/site-packages/airflow/utils/operator_helpers.py", line 252, in run
    return self.func(*args, **kwargs)
  File "/home/user/airflow/dags/test_jupyter.py", line 13, in run_notebook
    pm.execute_notebook(
  File "/home/user/.local/lib/python3.10/site-packages/papermill/execute.py", line 116, in execute_notebook
    nb = papermill_engines.execute_notebook_with_engine(
  File "/home/user/.local/lib/python3.10/site-packages/papermill/engines.py", line 48, in execute_notebook_with_engine
    return self.get_engine(engine_name).execute_notebook(nb, kernel_name, **kwargs)
  File "/home/user/.local/lib/python3.10/site-packages/papermill/engines.py", line 370, in execute_notebook
    cls.execute_managed_notebook(nb_man, kernel_name, log_output=log_output, **kwargs)
  File "/home/user/.local/lib/python3.10/site-packages/papermill/engines.py", line 442, in execute_managed_notebook
    return PapermillNotebookClient(nb_man, **final_kwargs).execute()
  File "/home/user/.local/lib/python3.10/site-packages/papermill/clientwrap.py", line 43, in execute
    with self.setup_kernel(**kwargs):
  File "/usr/lib/python3.10/contextlib.py", line 135, in __enter__
    return next(self.gen)
  File "/home/user/.local/lib/python3.10/site-packages/nbclient/client.py", line 600, in setup_kernel
    self.start_new_kernel(**kwargs)
  File "/home/user/.local/lib/python3.10/site-packages/jupyter_core/utils/__init__.py", line 165, in wrapped
    return loop.run_until_complete(inner)
  File "/usr/lib/python3.10/asyncio/base_events.py", line 649, in run_until_complete
    return future.result()
  File "/home/user/.local/lib/python3.10/site-packages/nbclient/client.py", line 550, in async_start_new_kernel
    await ensure_async(self.km.start_kernel(extra_arguments=self.extra_arguments, **kwargs))
  File "/home/user/.local/lib/python3.10/site-packages/jupyter_core/utils/__init__.py", line 198, in ensure_async
    result = await obj
  File "/home/user/.local/lib/python3.10/site-packages/jupyter_client/manager.py", line 96, in wrapper
    raise e
  File "/home/user/.local/lib/python3.10/site-packages/jupyter_client/manager.py", line 87, in wrapper
    out = await method(self, *args, **kwargs)
  File "/home/user/.local/lib/python3.10/site-packages/jupyter_client/manager.py", line 435, in _async_start_kernel
    kernel_cmd, kw = await self._async_pre_start_kernel(**kw)
  File "/home/user/.local/lib/python3.10/site-packages/jupyter_client/manager.py", line 397, in _async_pre_start_kernel
    self.kernel_spec,
  File "/home/user/.local/lib/python3.10/site-packages/jupyter_client/manager.py", line 195, in kernel_spec
    self._kernel_spec = self.kernel_spec_manager.get_kernel_spec(self.kernel_name)
  File "/home/user/.local/lib/python3.10/site-packages/jupyter_client/kernelspec.py", line 285, in get_kernel_spec
    raise NoSuchKernel(kernel_name)
jupyter_client.kernelspec.NoSuchKernel: No such kernel named python3
[2024-08-27T09:35:42.561+0700] {local_task_job_runner.py:261} INFO - Task exited with return code 1
[2024-08-27T09:35:42.575+0700] {taskinstance.py:3891} INFO - 0 downstream tasks scheduled from follow-on schedule check
[2024-08-27T09:35:42.575+0700] {local_task_job_runner.py:240} INFO - ::endgroup::
