[2024-08-26T08:12:47.713+0700] {local_task_job_runner.py:123} INFO - ::group::Pre task execution logs
[2024-08-26T08:12:47.727+0700] {taskinstance.py:2603} INFO - Dependencies all met for dep_context=non-requeueable deps ti=<TaskInstance: combine_columns_dag.combine_columns scheduled__2024-01-05T00:00:00+00:00 [queued]>
[2024-08-26T08:12:47.732+0700] {taskinstance.py:2603} INFO - Dependencies all met for dep_context=requeueable deps ti=<TaskInstance: combine_columns_dag.combine_columns scheduled__2024-01-05T00:00:00+00:00 [queued]>
[2024-08-26T08:12:47.732+0700] {taskinstance.py:2856} INFO - Starting attempt 1 of 2
[2024-08-26T08:12:47.746+0700] {taskinstance.py:2879} INFO - Executing <Task(PythonOperator): combine_columns> on 2024-01-05 00:00:00+00:00
[2024-08-26T08:12:47.752+0700] {standard_task_runner.py:72} INFO - Started process 11174 to run task
[2024-08-26T08:12:47.769+0700] {standard_task_runner.py:104} INFO - Running: ['airflow', 'tasks', 'run', 'combine_columns_dag', 'combine_columns', 'scheduled__2024-01-05T00:00:00+00:00', '--job-id', '70', '--raw', '--subdir', 'DAGS_FOLDER/test_pandas.py', '--cfg-path', '/tmp/tmpss6jvqld']
[2024-08-26T08:12:47.770+0700] {standard_task_runner.py:105} INFO - Job 70: Subtask combine_columns
[2024-08-26T08:12:47.804+0700] {task_command.py:467} INFO - Running <TaskInstance: combine_columns_dag.combine_columns scheduled__2024-01-05T00:00:00+00:00 [running]> on host LAPTOP-G8FSBU09.
[2024-08-26T08:12:47.860+0700] {taskinstance.py:3122} INFO - Exporting env vars: AIRFLOW_CTX_DAG_OWNER='airflow' AIRFLOW_CTX_DAG_ID='combine_columns_dag' AIRFLOW_CTX_TASK_ID='combine_columns' AIRFLOW_CTX_EXECUTION_DATE='2024-01-05T00:00:00+00:00' AIRFLOW_CTX_TRY_NUMBER='1' AIRFLOW_CTX_DAG_RUN_ID='scheduled__2024-01-05T00:00:00+00:00'
[2024-08-26T08:12:47.861+0700] {logging_mixin.py:190} INFO - Task instance is in running state
[2024-08-26T08:12:47.861+0700] {logging_mixin.py:190} INFO -  Previous state of the Task instance: queued
[2024-08-26T08:12:47.861+0700] {logging_mixin.py:190} INFO - Current task name:combine_columns state:running start_date:2024-08-26 01:12:47.727553+00:00
[2024-08-26T08:12:47.861+0700] {logging_mixin.py:190} INFO - Dag name:combine_columns_dag and current dag run status:running
[2024-08-26T08:12:47.861+0700] {taskinstance.py:731} INFO - ::endgroup::
[2024-08-26T08:12:47.866+0700] {taskinstance.py:3301} ERROR - Task failed with exception
Traceback (most recent call last):
  File "/home/user/.local/lib/python3.10/site-packages/pandas/core/indexes/base.py", line 3805, in get_loc
    return self._engine.get_loc(casted_key)
  File "index.pyx", line 167, in pandas._libs.index.IndexEngine.get_loc
  File "index.pyx", line 196, in pandas._libs.index.IndexEngine.get_loc
  File "pandas/_libs/hashtable_class_helper.pxi", line 7081, in pandas._libs.hashtable.PyObjectHashTable.get_item
  File "pandas/_libs/hashtable_class_helper.pxi", line 7089, in pandas._libs.hashtable.PyObjectHashTable.get_item
KeyError: 'a'

The above exception was the direct cause of the following exception:

Traceback (most recent call last):
  File "/home/user/.local/lib/python3.10/site-packages/airflow/models/taskinstance.py", line 767, in _execute_task
    result = _execute_callable(context=context, **execute_callable_kwargs)
  File "/home/user/.local/lib/python3.10/site-packages/airflow/models/taskinstance.py", line 733, in _execute_callable
    return ExecutionCallableRunner(
  File "/home/user/.local/lib/python3.10/site-packages/airflow/utils/operator_helpers.py", line 252, in run
    return self.func(*args, **kwargs)
  File "/home/user/.local/lib/python3.10/site-packages/airflow/models/baseoperator.py", line 406, in wrapper
    return func(self, *args, **kwargs)
  File "/home/user/.local/lib/python3.10/site-packages/airflow/operators/python.py", line 238, in execute
    return_value = self.execute_callable()
  File "/home/user/.local/lib/python3.10/site-packages/airflow/operators/python.py", line 256, in execute_callable
    return runner.run(*self.op_args, **self.op_kwargs)
  File "/home/user/.local/lib/python3.10/site-packages/airflow/utils/operator_helpers.py", line 252, in run
    return self.func(*args, **kwargs)
  File "/home/user/airflow/dags/test_pandas.py", line 16, in comb_col
    df['combined']= df['a'].astype(str) + df['b'].astype(str)
  File "/home/user/.local/lib/python3.10/site-packages/pandas/core/frame.py", line 4102, in __getitem__
    indexer = self.columns.get_loc(key)
  File "/home/user/.local/lib/python3.10/site-packages/pandas/core/indexes/base.py", line 3812, in get_loc
    raise KeyError(key) from err
KeyError: 'a'
[2024-08-26T08:12:47.875+0700] {logging_mixin.py:190} INFO - Task instance in failure state
[2024-08-26T08:12:47.875+0700] {logging_mixin.py:190} INFO - Task start:2024-08-26 01:12:47.727553+00:00 end:2024-08-26 01:12:47.874670+00:00 duration:0.147117
[2024-08-26T08:12:47.875+0700] {logging_mixin.py:190} INFO - Task:<Task(PythonOperator): combine_columns> dag:<DAG: combine_columns_dag> dagrun:<DagRun combine_columns_dag @ 2024-01-05 00:00:00+00:00: scheduled__2024-01-05T00:00:00+00:00, state:running, queued_at: 2024-08-26 01:12:45.804710+00:00. externally triggered: False>
[2024-08-26T08:12:47.875+0700] {logging_mixin.py:190} INFO - Failure caused by 'a'
[2024-08-26T08:12:47.875+0700] {taskinstance.py:1225} INFO - Marking task as UP_FOR_RETRY. dag_id=combine_columns_dag, task_id=combine_columns, run_id=scheduled__2024-01-05T00:00:00+00:00, execution_date=20240105T000000, start_date=20240826T011247, end_date=20240826T011247
[2024-08-26T08:12:47.890+0700] {taskinstance.py:340} INFO - ::group::Post task execution logs
[2024-08-26T08:12:47.890+0700] {standard_task_runner.py:124} ERROR - Failed to execute job 70 for task combine_columns ('a'; 11174)
Traceback (most recent call last):
  File "/home/user/.local/lib/python3.10/site-packages/pandas/core/indexes/base.py", line 3805, in get_loc
    return self._engine.get_loc(casted_key)
  File "index.pyx", line 167, in pandas._libs.index.IndexEngine.get_loc
  File "index.pyx", line 196, in pandas._libs.index.IndexEngine.get_loc
  File "pandas/_libs/hashtable_class_helper.pxi", line 7081, in pandas._libs.hashtable.PyObjectHashTable.get_item
  File "pandas/_libs/hashtable_class_helper.pxi", line 7089, in pandas._libs.hashtable.PyObjectHashTable.get_item
KeyError: 'a'

The above exception was the direct cause of the following exception:

Traceback (most recent call last):
  File "/home/user/.local/lib/python3.10/site-packages/airflow/task/task_runner/standard_task_runner.py", line 117, in _start_by_fork
    ret = args.func(args, dag=self.dag)
  File "/home/user/.local/lib/python3.10/site-packages/airflow/cli/cli_config.py", line 49, in command
    return func(*args, **kwargs)
  File "/home/user/.local/lib/python3.10/site-packages/airflow/utils/cli.py", line 115, in wrapper
    return f(*args, **kwargs)
  File "/home/user/.local/lib/python3.10/site-packages/airflow/cli/commands/task_command.py", line 483, in task_run
    task_return_code = _run_task_by_selected_method(args, _dag, ti)
  File "/home/user/.local/lib/python3.10/site-packages/airflow/cli/commands/task_command.py", line 256, in _run_task_by_selected_method
    return _run_raw_task(args, ti)
  File "/home/user/.local/lib/python3.10/site-packages/airflow/cli/commands/task_command.py", line 341, in _run_raw_task
    return ti._run_raw_task(
  File "/home/user/.local/lib/python3.10/site-packages/airflow/utils/session.py", line 97, in wrapper
    return func(*args, session=session, **kwargs)
  File "/home/user/.local/lib/python3.10/site-packages/airflow/models/taskinstance.py", line 2995, in _run_raw_task
    return _run_raw_task(
  File "/home/user/.local/lib/python3.10/site-packages/airflow/models/taskinstance.py", line 273, in _run_raw_task
    TaskInstance._execute_task_with_callbacks(
  File "/home/user/.local/lib/python3.10/site-packages/airflow/models/taskinstance.py", line 3149, in _execute_task_with_callbacks
    result = self._execute_task(context, task_orig)
  File "/home/user/.local/lib/python3.10/site-packages/airflow/models/taskinstance.py", line 3173, in _execute_task
    return _execute_task(self, context, task_orig)
  File "/home/user/.local/lib/python3.10/site-packages/airflow/models/taskinstance.py", line 767, in _execute_task
    result = _execute_callable(context=context, **execute_callable_kwargs)
  File "/home/user/.local/lib/python3.10/site-packages/airflow/models/taskinstance.py", line 733, in _execute_callable
    return ExecutionCallableRunner(
  File "/home/user/.local/lib/python3.10/site-packages/airflow/utils/operator_helpers.py", line 252, in run
    return self.func(*args, **kwargs)
  File "/home/user/.local/lib/python3.10/site-packages/airflow/models/baseoperator.py", line 406, in wrapper
    return func(self, *args, **kwargs)
  File "/home/user/.local/lib/python3.10/site-packages/airflow/operators/python.py", line 238, in execute
    return_value = self.execute_callable()
  File "/home/user/.local/lib/python3.10/site-packages/airflow/operators/python.py", line 256, in execute_callable
    return runner.run(*self.op_args, **self.op_kwargs)
  File "/home/user/.local/lib/python3.10/site-packages/airflow/utils/operator_helpers.py", line 252, in run
    return self.func(*args, **kwargs)
  File "/home/user/airflow/dags/test_pandas.py", line 16, in comb_col
    df['combined']= df['a'].astype(str) + df['b'].astype(str)
  File "/home/user/.local/lib/python3.10/site-packages/pandas/core/frame.py", line 4102, in __getitem__
    indexer = self.columns.get_loc(key)
  File "/home/user/.local/lib/python3.10/site-packages/pandas/core/indexes/base.py", line 3812, in get_loc
    raise KeyError(key) from err
KeyError: 'a'
[2024-08-26T08:12:47.933+0700] {local_task_job_runner.py:261} INFO - Task exited with return code 1
[2024-08-26T08:12:47.945+0700] {taskinstance.py:3891} INFO - 0 downstream tasks scheduled from follow-on schedule check
[2024-08-26T08:12:47.945+0700] {local_task_job_runner.py:240} INFO - ::endgroup::
[2024-08-26T08:14:23.677+0700] {local_task_job_runner.py:123} INFO - ::group::Pre task execution logs
[2024-08-26T08:14:23.686+0700] {taskinstance.py:2603} INFO - Dependencies all met for dep_context=non-requeueable deps ti=<TaskInstance: combine_columns_dag.combine_columns scheduled__2024-01-05T00:00:00+00:00 [queued]>
[2024-08-26T08:14:23.691+0700] {taskinstance.py:2603} INFO - Dependencies all met for dep_context=requeueable deps ti=<TaskInstance: combine_columns_dag.combine_columns scheduled__2024-01-05T00:00:00+00:00 [queued]>
[2024-08-26T08:14:23.692+0700] {taskinstance.py:2856} INFO - Starting attempt 1 of 2
[2024-08-26T08:14:23.712+0700] {taskinstance.py:2879} INFO - Executing <Task(PythonOperator): combine_columns> on 2024-01-05 00:00:00+00:00
[2024-08-26T08:14:23.728+0700] {standard_task_runner.py:72} INFO - Started process 12242 to run task
[2024-08-26T08:14:23.735+0700] {standard_task_runner.py:104} INFO - Running: ['airflow', 'tasks', 'run', 'combine_columns_dag', 'combine_columns', 'scheduled__2024-01-05T00:00:00+00:00', '--job-id', '71', '--raw', '--subdir', 'DAGS_FOLDER/test_pandas.py', '--cfg-path', '/tmp/tmp7ct75x4p']
[2024-08-26T08:14:23.736+0700] {standard_task_runner.py:105} INFO - Job 71: Subtask combine_columns
[2024-08-26T08:14:23.794+0700] {task_command.py:467} INFO - Running <TaskInstance: combine_columns_dag.combine_columns scheduled__2024-01-05T00:00:00+00:00 [running]> on host LAPTOP-G8FSBU09.
[2024-08-26T08:14:23.875+0700] {taskinstance.py:3122} INFO - Exporting env vars: AIRFLOW_CTX_DAG_OWNER='airflow' AIRFLOW_CTX_DAG_ID='combine_columns_dag' AIRFLOW_CTX_TASK_ID='combine_columns' AIRFLOW_CTX_EXECUTION_DATE='2024-01-05T00:00:00+00:00' AIRFLOW_CTX_TRY_NUMBER='1' AIRFLOW_CTX_DAG_RUN_ID='scheduled__2024-01-05T00:00:00+00:00'
[2024-08-26T08:14:23.877+0700] {logging_mixin.py:190} INFO - Task instance is in running state
[2024-08-26T08:14:23.877+0700] {logging_mixin.py:190} INFO -  Previous state of the Task instance: queued
[2024-08-26T08:14:23.877+0700] {logging_mixin.py:190} INFO - Current task name:combine_columns state:running start_date:2024-08-26 01:14:23.687052+00:00
[2024-08-26T08:14:23.878+0700] {logging_mixin.py:190} INFO - Dag name:combine_columns_dag and current dag run status:running
[2024-08-26T08:14:23.878+0700] {taskinstance.py:731} INFO - ::endgroup::
[2024-08-26T08:14:23.921+0700] {python.py:240} INFO - Done. Returned value was: None
[2024-08-26T08:14:23.927+0700] {taskinstance.py:340} INFO - ::group::Post task execution logs
[2024-08-26T08:14:23.927+0700] {taskinstance.py:352} INFO - Marking task as SUCCESS. dag_id=combine_columns_dag, task_id=combine_columns, run_id=scheduled__2024-01-05T00:00:00+00:00, execution_date=20240105T000000, start_date=20240826T011423, end_date=20240826T011423
[2024-08-26T08:14:23.944+0700] {logging_mixin.py:190} INFO - Task instance in success state
[2024-08-26T08:14:23.945+0700] {logging_mixin.py:190} INFO -  Previous state of the Task instance: running
[2024-08-26T08:14:23.945+0700] {logging_mixin.py:190} INFO - Dag name:combine_columns_dag queued_at:2024-08-26 01:14:21.458412+00:00
[2024-08-26T08:14:23.945+0700] {logging_mixin.py:190} INFO - Task hostname:LAPTOP-G8FSBU09. operator:PythonOperator
[2024-08-26T08:14:23.988+0700] {local_task_job_runner.py:261} INFO - Task exited with return code 0
[2024-08-26T08:14:23.998+0700] {taskinstance.py:3891} INFO - 0 downstream tasks scheduled from follow-on schedule check
[2024-08-26T08:14:23.999+0700] {local_task_job_runner.py:240} INFO - ::endgroup::
